<?xml version="1.0" encoding="utf-8"?>

<robot name="myrobot" xmlns:xacro="http://www.ros.org/wiki/xacro">

	  <xacro:property name="cameraSize" value="0.03"/>
  	  <xacro:property name="cameraMass" value="0.0001"/>
	  <xacro:include filename="$(find mybot_description)/urdf/mybot.gazebo" />
	  <xacro:include filename="$(find mybot_description)/urdf/materials.xacro" />
	  <xacro:include filename="$(find mybot_description)/urdf/macros.xacro" />


  <link
    name="chassis">
    <inertial>
      <origin
        xyz="0.018957 -0.0034534 0.20396"
        rpy="0 0 0" />
      <mass
        value="0.6353" />
      <inertia
        ixx="0.018752"
        ixy="-1.3295E-05"
        ixz="0.0012594"
        iyy="0.022099"
        iyz="0.0003545"
        izz="0.02535" />
    </inertial>
    <visual>
      <origin
        xyz="0 0 0"
        rpy="0 0 0" />
      <geometry>
        <mesh
          filename="package://mybot_description/meshes/chassis.dae" />
      </geometry>
      <material name="">
        <color rgba="0.43922 0.43922 0.43922 1" />
      </material>
    </visual>
    <collision>
      <origin
        xyz="0 0 0"
        rpy="0 0 0" />
      <geometry>
        <mesh filename="package://mybot_description/meshes/chassis.dae" />
      </geometry>
    </collision>
  </link>
  <link
    name="front_left_wheel">
    <inertial>
      <origin
        xyz="-1.6838E-06 3.36E-07 6.9398E-05"
        rpy="0 0 1" />
      <mass
        value="0.15984" />
      <inertia
        ixx="0.00025061"
        ixy="1.0824E-08"
        ixz="5.5158E-09"
        iyy="0.0002506"
        iyz="-2.2109E-08"
        izz="0.00044609" />
    </inertial>
    <visual>
      <origin
        xyz="0 0 0"
        rpy="0 0 0" />
      <geometry>
        <mesh
          filename="package://mybot_description/meshes/front_left_wheel.dae" />
      </geometry>
      <material
        name="">
        <color
          rgba="0.1098 0.1098 0.1098 1" />
      </material>
    </visual>
    <collision>
      <origin
        xyz="0 0 0"
        rpy="0 0 0" />
      <geometry>
        <mesh
          filename="package://mybot_description/meshes/front_left_wheel.dae" />
      </geometry>
    </collision>
  </link>
  <joint
    name="front_left_wheel_hinge"
    type="continuous">
    <origin
      xyz="0.23232 0.18046 0.063906"
      rpy="1.5708 -0.89583 3.1416" />
    <parent
      link="chassis" />
    <child
      link="front_left_wheel" />
    <axis
      xyz="0 0 1" />
    <limit
      effort="1000"
      velocity="1500" />
  </joint>
  <link
    name="middle_left_wheel">
    <inertial>
      <origin
        xyz="-1.6618E-06 3.1989E-07 6.9398E-05"
        rpy="0 0 1" />
      <mass
        value="0.15984" />
      <inertia
        ixx="0.00025061"
        ixy="1.0825E-08"
        ixz="5.5201E-09"
        iyy="0.0002506"
        iyz="-2.2123E-08"
        izz="0.00044609" />
    </inertial>
    <visual>
      <origin
        xyz="0 0 0"
        rpy="0 0 0" />
      <geometry>
        <mesh
          filename="package://mybot_description/meshes/middle_left_wheel.dae" />
      </geometry>
      <material
        name="">
        <color
          rgba="0.1098 0.1098 0.1098 1" />
      </material>
    </visual>
    <collision>
      <origin
        xyz="0 0 0"
        rpy="0 0 0" />
      <geometry>
        <mesh
          filename="package://mybot_description/meshes/middle_left_wheel.dae" />
      </geometry>
    </collision>
  </link>
  <joint
    name="middle_left_wheel_hinge"
    type="continuous">
    <origin
      xyz="0.0024254 0.17526 0.07597"
      rpy="-1.5708 0.13003 0" />
    <parent
      link="chassis" />
    <child
      link="middle_left_wheel" />
    <axis
      xyz="0 0 1" />
    <limit
      effort="1000"
      velocity="1500" />
  </joint>
  <link
    name="rear_left_wheel">
    <inertial>
      <origin
        xyz="-1.6618E-06 3.1995E-07 6.9398E-05"
        rpy="0 0 1" />
      <mass
        value="0.15984" />
      <inertia
        ixx="0.00025061"
        ixy="1.0825E-08"
        ixz="5.5202E-09"
        iyy="0.0002506"
        iyz="-2.2123E-08"
        izz="0.00044609" />
    </inertial>
    <visual>
      <origin
        xyz="0 0 0"
        rpy="0 0 0" />
      <geometry>
        <mesh
          filename="package://mybot_description/meshes/rear_left_wheel.dae" />
      </geometry>
      <material
        name="">
        <color
          rgba="0.1098 0.1098 0.1098 1" />
      </material>
    </visual>
    <collision>
      <origin
        xyz="0 0 0"
        rpy="0 0 0" />
      <geometry>
        <mesh
          filename="package://mybot_description/meshes/rear_left_wheel.dae" />
      </geometry>
    </collision>
  </link>
  <joint
    name="rear_left_wheel_hinge"
    type="continuous">
    <origin
      xyz="-0.20669 0.18075 0.10332"
      rpy="-1.5708 0.13003 0" />
    <parent
      link="chassis" />
    <child
      link="rear_left_wheel" />
    <axis
      xyz="0 0 1" />
    <limit
      effort="1000"
      velocity="1500" />
  </joint>
  <link
    name="front_right_wheel">
    <inertial>
      <origin
        xyz="-1.6829E-06 3.3642E-07 6.9398E-05"
        rpy="0 0 1" />
      <mass
        value="0.15984" />
      <inertia
        ixx="0.00025061"
        ixy="1.0824E-08"
        ixz="5.5162E-09"
        iyy="0.0002506"
        iyz="-2.2109E-08"
        izz="0.00044609" />
    </inertial>
    <visual>
      <origin
        xyz="0 0 0"
        rpy="0 0 0" />
      <geometry>
        <mesh
          filename="package://mybot_description/meshes/front_right_wheel.dae" />
      </geometry>
      <material
        name="">
        <color
          rgba="0.1098 0.1098 0.1098 1" />
      </material>
    </visual>
    <collision>
      <origin
        xyz="0 0 0"
        rpy="0 0 0" />
      <geometry>
        <mesh
          filename="package://mybot_description/meshes/front_right_wheel.dae" />
      </geometry>
    </collision>
  </link>
  <joint
    name="front_right_wheel_hinge"
    type="continuous">
    <origin
      xyz="0.23232 -0.17674 0.063906"
      rpy="-1.5708 -0.98023 3.1416" />
    <parent
      link="chassis" />
    <child
      link="front_right_wheel" />
    <axis
      xyz="0 0 -1" />
    <limit
      effort="1000"
      velocity="1500" />
  </joint>
  <link
    name="middle_right_wheel">
    <inertial>
      <origin
        xyz="-1.6854E-06 3.3882E-07 6.9398E-05"
        rpy="0 0 1" />
      <mass
        value="0.15984" />
      <inertia
        ixx="0.00025061"
        ixy="1.0824E-08"
        ixz="5.5158E-09"
        iyy="0.0002506"
        iyz="-2.2107E-08"
        izz="0.00044609" />
    </inertial>
    <visual>
      <origin
        xyz="0 0 0"
        rpy="0 0 0" />
      <geometry>
        <mesh
          filename="package://mybot_description/meshes/middle_right_wheel.dae" />
      </geometry>
      <material
        name="">
        <color
          rgba="0.1098 0.1098 0.1098 1" />
      </material>
    </visual>
    <collision>
      <origin
        xyz="0 0 0"
        rpy="0 0 0" />
      <geometry>
        <mesh
          filename="package://mybot_description/meshes/middle_right_wheel.dae" />
      </geometry>
    </collision>
  </link>
  <joint
    name="middle_right_wheel_hinge"
    type="continuous">
    <origin
      xyz="0.0024254 -0.17674 0.07597"
      rpy="1.5708 0.8354 0" />
    <parent
      link="chassis" />
    <child
      link="middle_right_wheel" />
    <axis
      xyz="0 0 -1" />
    <limit
      effort="1000"
      velocity="1500" />
  </joint>
  <link
    name="rear_right_wheel">
    <inertial>
      <origin
        xyz="-1.6748E-06 3.3089E-07 6.9397E-05"
        rpy="0 0 1" />
      <mass
        value="0.15984" />
      <inertia
        ixx="0.00025061"
        ixy="1.0824E-08"
        ixz="5.5178E-09"
        iyy="0.0002506"
        iyz="-2.2114E-08"
        izz="0.00044609" />
    </inertial>
    <visual>
      <origin
        xyz="0 0 0"
        rpy="0 0 0" />
      <geometry>
        <mesh
          filename="package://mybot_description/meshes/rear_right_wheel.dae" />
      </geometry>
      <material
        name="">
        <color
          rgba="0.1098 0.1098 0.1098 1" />
      </material>
    </visual>
    <collision>
      <origin
        xyz="0 0 0"
        rpy="0 0 0" />
      <geometry>
        <mesh
          filename="package://mybot_description/meshes/rear_right_wheel.dae" />
      </geometry>
    </collision>
  </link>
  <joint
    name="rear_right_wheel_hinge"
    type="continuous">
    <origin
      xyz="-0.20669 -0.17674 0.10332"
      rpy="1.5708 0.53382 0" />
    <parent
      link="chassis" />
    <child
      link="rear_right_wheel" />
    <axis
      xyz="0 0 -1" />
    <limit
      effort="1000"
      velocity="1500" />
  </joint>




	  <link name="camera">
	    <collision>
	      <origin xyz="0 0 0" rpy="0 0 0"/>
	      <geometry>
		<box size="${cameraSize} ${cameraSize} ${cameraSize}"/>
	      </geometry>
	    </collision>
	    <visual>
	      <origin xyz="0 0 0" rpy="0 0 0"/>
	      <transparency>1</transparency>
	      <geometry>
		<box size="${cameraSize} ${cameraSize} ${cameraSize}"/>
	      </geometry>
	      <material name="transparent"/>
	    </visual>
	    <inertial>
	      <mass value="${cameraMass}" />
              <material name="transparent"/>
              <transparency>1</transparency>
	      <origin xyz="0 0 0" rpy="0 0 0"/>
	      <box_inertia m="${cameraMass}" x="${cameraSize}" y="${cameraSize}" z="${cameraSize}" />
	      <inertia ixx="0" ixy="0" ixz="0" iyy="0" iyz="0" izz="0" />
	    </inertial>
	  </link>

	  <joint name="camera_joint" type="fixed">
	    <axis xyz="0 0 0" />
	    <origin xyz="0.099 0.0 0.230" rpy="0 0 0"/>
	    <parent link="chassis"/>
	    <child link="camera"/>
            <material name="transparent"/>
            <transparency>1</transparency>
	  </joint>


	  <joint name="hokuyo_joint" type="fixed">
	    <axis xyz="0 0 0" />
	    <origin xyz="0.04 0.0 0.285" rpy="0 0 0"/>
	    <parent link="chassis"/>
	    <child link="hokuyo"/>
	  </joint>

	  <!-- Hokuyo Laser -->
	  <link name="hokuyo">
	    <collision>
	      <origin xyz="0 0 0" rpy="0 0 0"/>
	      <geometry>
	    <box size="0.1 0.1 0.1"/>
	      </geometry>
	    </collision>
	    <visual>
	      <origin xyz="0 0 0" rpy="0 0 0"/>
	      <material name="transparent"/>
	      <transparency>1</transparency>
	      <geometry>
		<mesh filename="package://mybot_description/meshes/hokuyo.dae"/>
	      </geometry>
	    </visual>
	    <inertial>
	      <mass value="0.000000001" />
	      <origin xyz="0 0 0" rpy="0 0 0"/>
	      <inertia ixx="0" ixy="0" ixz="0" iyy="0" iyz="0" izz="0" />
	    </inertial>
	  </link>

</robot>
